<?xml version="1.0"?>
<robot name="nanook">
	<!-- base_link -->
	<link name = 'base_link'>
		<visual>
      <geometry>
        <box size="0.8 0.5 0.4"/>
      </geometry>
      <material name="silver">
        <color rgba="0.75 0.75 0.75 1"/>
      </material>
		</visual>

    <collision>
      <geometry>
        <box size="0.8 0.5 0.4"/>
      </geometry>
    </collision>
	</link>

	<!-- front_right_wheel -->
  <link name="front_right_wheel">
    <visual>
      <geometry>
        <cylinder length="0.05" radius="0.1"/>
      </geometry>
      <material name="black"/>
    </visual>

    <collision>
      <geometry>
        <cylinder length="0.05" radius="0.1"/>
      </geometry>
    </collision>
  </link>

  <joint name="front_right_wheel_joint" type="continuous">
    <axis xyz="0 0 1"/>
    <parent link="base_link"/>
    <child link="front_right_wheel"/>
    <origin rpy="-1.5708 0 0" xyz="0.25 -0.275 -0.15"/>
  </joint>

	<!-- middle_right_wheel -->

  <link name="middle_right_wheel">
    <visual>
      <geometry>
        <cylinder length="0.05" radius="0.1"/>
      </geometry>
      <material name="black"/>
    </visual>

    <collision>
      <geometry>
        <cylinder length="0.05" radius="0.1"/>
      </geometry>
    </collision>
  </link>

  <joint name="middle_right_wheel_joint" type="continuous">
    <axis xyz="0 0 1"/>
    <parent link="base_link"/>
    <child link="middle_right_wheel"/>
    <origin rpy="-1.5708 0 0" xyz="0 -0.275 -0.15"/>
  </joint>

	<!-- back_right_wheel -->

  <link name="back_right_wheel">
    <visual>
      <geometry>
        <cylinder length="0.05" radius="0.1"/>
      </geometry>
      <material name="black"/>
    </visual>

    <collision>
      <geometry>
        <cylinder length="0.05" radius="0.1"/>
      </geometry>
    </collision>
  </link>

  <joint name="back_right_wheel_joint" type="continuous">
    <axis xyz="0 0 1"/>
    <parent link="base_link"/>
    <child link="back_right_wheel"/>
    <origin rpy="-1.5708 0 0" xyz="-0.25 -0.275 -0.15"/>
  </joint>

	<!-- front_left_wheel -->

  <link name="front_left_wheel">
    <visual>
      <geometry>
        <cylinder length="0.05" radius="0.1"/>
      </geometry>
      <material name="black"/>
    </visual>

    <collision>
      <geometry>
        <cylinder length="0.05" radius="0.1"/>
      </geometry>
    </collision>
  </link>

  <joint name="front_left_wheel_joint" type="continuous">
    <axis xyz="0 0 1"/>
    <parent link="base_link"/>
    <child link="front_left_wheel"/>
    <origin rpy="-1.5708 0 0" xyz="0.25 0.275 -0.15"/>
  </joint>

	<!-- middle_left_wheel -->

  <link name="middle_left_wheel">
    <visual>
      <geometry>
        <cylinder length="0.05" radius="0.1"/>
      </geometry>
      <material name="black"/>
    </visual>

    <collision>
      <geometry>
        <cylinder length="0.05" radius="0.1"/>
      </geometry>
    </collision>
  </link>

  <joint name="middle_left_wheel_joint" type="continuous">
    <axis xyz="0 0 1"/>
    <parent link="base_link"/>
    <child link="middle_left_wheel"/>
    <origin rpy="-1.5708 0 0" xyz="0 0.275 -0.15"/>
  </joint>

	<!-- back_left_wheel -->

  <link name="back_left_wheel">
    <visual>
      <geometry>
        <cylinder length="0.05" radius="0.1"/>
      </geometry>
      <material name="black"/>
    </visual>

    <collision>
      <geometry>
        <cylinder length="0.05" radius="0.1"/>
      </geometry>
    </collision>
  </link>

  <joint name="back_left_wheel_joint" type="continuous">
    <axis xyz="0 0 1"/>
    <parent link="base_link"/>
    <child link="back_left_wheel"/>
    <origin rpy="-1.5708 0 0" xyz="-0.25 0.275 -0.15"/>
  </joint>
</robot>
